Workbook

Sheet Country or Territory
D2: Chris | E2: Maggie | F2: Allyson | G2: Eddy
C3: Expanded list: | D3: =COUNTA(D7:D231) -> 146 | E3: =COUNTA(E7:E231) -> 138 | F3: =COUNTA(F7:F231) -> 69 | G3: =COUNTA(G7:G231) -> 60
C4: UN Member States only: | D4: =COUNTIFS($C$7:$C$231, "Sovereign", D7:D231, "<>") -> 129 | E4: =COUNTIFS($C$7:$C$231, "Sovereign", E7:E231, "<>") -> 119 | F4: =COUNTIFS($C$7:$C$231, "Sovereign", F7:F231, "<>") -> 62 | G4: =COUNTIFS($C$7:$C$231, "Sovereign", G7:G231, "<>") -> 54
A6: Code | B6: Name | C6: Status | D6: Chris | E6: Maggie | F6: Allyson | G6: Edward
A7: =VLOOKUP(Table1[[#This Row],[Name]],'country codes'!$A$1:$D$253,4,FALSE) -> AFG | B7: Afghanistan | C7: Sovereign | D7: Y
A8: =VLOOKUP(Table1[[#This Row],[Name]],'country codes'!$A$1:$D$253,4,FALSE) -> ALB | B8: Albania | C8: Sovereign | D8: Y | E8: Y
A9: =VLOOKUP(Table1[[#This Row],[Name]],'country codes'!$A$1:$D$253,4,FALSE) -> DZA | B9: Algeria | C9: Sovereign
A10: =VLOOKUP(Table1[[#This Row],[Name]],'country codes'!$A$1:$D$253,4,FALSE) -> ASM | B10: American Samoa | C10: Non-sovereign | D10: Y | E10: Y
A11: =VLOOKUP(Table1[[#This Row],[Name]],'country codes'!$A$1:$D$253,4,FALSE) -> AND | B11: Andorra | C11: Sovereign
A12: =VLOOKUP(Table1[[#This Row],[Name]],'country codes'!$A$1:$D$253,4,FALSE) -> AGO | B12: Angola | C12: Sovereign
A13: =VLOOKUP(Table1[[#This Row],[Name]],'country codes'!$A$1:$D$253,4,FALSE) -> ATG | B13: Antigua and Barbuda | C13: Sovereign | D13: Y | E13: Y | F13: Y | G13: Y
A14: =VLOOKUP(Table1[[#This Row],[Name]],'country codes'!$A$1:$D$253,4,FALSE) -> ARG | B14: Argentina | C14: Sovereign | D14: Y | E14: Y | F14: Y | G14: Y
A15: =VLOOKUP(Table1[[#This Row],[Name]],'country codes'!$A$1:$D$253,4,FALSE) -> ARM | B15: Armenia | C15: Sovereign | D15: Y | E15: Y
A16: =VLOOKUP(Table1[[#This Row],[Name]],'country codes'!$A$1:$D$253,4,FALSE) -> ABW | B16: Aruba | C16: Non-sovereign | D16: Y | E16: Y | F16: Y | G16: Y
A17: =VLOOKUP(Table1[[#This Row],[Name]],'country codes'!$A$1:$D$253,4,FALSE) -> AUS | B17: Australia | C17: Sovereign | D17: Y | E17: Y | F17: Y | G17: Y
A18: =VLOOKUP(Table1[[#This Row],[Name]],'country codes'!$A$1:$D$253,4,FALSE) -> AUT | B18: Austria | C18: Sovereign | D18: Y | E18: Y | F18: Y | G18: Y
A19: =VLOOKUP(Table1[[#This Row],[Name]],'country codes'!$A$1:$D$253,4,FALSE) -> AZE | B19: Azerbaijan | C19: Sovereign | D19: Y | E19: Y
A20: =VLOOKUP(Table1[[#This Row],[Name]],'country codes'!$A$1:$D$253,4,FALSE) -> PT-20 | B20: Azores | C20: Non-sovereign
A21: =VLOOKUP(Table1[[#This Row],[Name]],'country codes'!$A$1:$D$253,4,FALSE) -> BHR | B21: Bahrain | C21: Sovereign
A22: =VLOOKUP(Table1[[#This Row],[Name]],'country codes'!$A$1:$D$253,4,FALSE) -> BGD | B22: Bangladesh | C22: Sovereign
A23: =VLOOKUP(Table1[[#This Row],[Name]],'country codes'!$A$1:$D$253,4,FALSE) -> BRB | B23: Barbados | C23: Sovereign
A24: =VLOOKUP(Table1[[#This Row],[Name]],'country codes'!$A$1:$D$253,4,FALSE) -> BLR | B24: Belarus | C24: Sovereign
A25: =VLOOKUP(Table1[[#This Row],[Name]],'country codes'!$A$1:$D$253,4,FALSE) -> BEL | B25: Belgium | C25: Sovereign | D25: Y | E25: Y
A26: =VLOOKUP(Table1[[#This Row],[Name]],'country codes'!$A$1:$D$253,4,FALSE) -> BLZ | B26: Belize | C26: Sovereign | D26: Y | E26: Y
A27: =VLOOKUP(Table1[[#This Row],[Name]],'country codes'!$A$1:$D$253,4,FALSE) -> BEN | B27: Benin | C27: Sovereign
A28: =VLOOKUP(Table1[[#This Row],[Name]],'country codes'!$A$1:$D$253,4,FALSE) -> BMU | B28: Bermuda | C28: Non-sovereign
A29: =VLOOKUP(Table1[[#This Row],[Name]],'country codes'!$A$1:$D$253,4,FALSE) -> BTN | B29: Bhutan | C29: Sovereign
A30: =VLOOKUP(Table1[[#This Row],[Name]],'country codes'!$A$1:$D$253,4,FALSE) -> BOL | B30: Bolivia | C30: Sovereign | E30: Y
A31: =VLOOKUP(Table1[[#This Row],[Name]],'country codes'!$A$1:$D$253,4,FALSE) -> BIH | B31: Bosnia and Herzegovina | C31: Sovereign | D31: Y | E31: Y
A32: =VLOOKUP(Table1[[#This Row],[Name]],'country codes'!$A$1:$D$253,4,FALSE) -> BWA | B32: Botswana | C32: Sovereign | D32: Y | E32: Y | F32: Y | G32: Y
A33: =VLOOKUP(Table1[[#This Row],[Name]],'country codes'!$A$1:$D$253,4,FALSE) -> BRA | B33: Brazil | C33: Sovereign | D33: Y | E33: Y | F33: Y | G33: Y
A34: =VLOOKUP(Table1[[#This Row],[Name]],'country codes'!$A$1:$D$253,4,FALSE) -> VGB | B34: British Virgin Islands | C34: Non-sovereign
A35: =VLOOKUP(Table1[[#This Row],[Name]],'country codes'!$A$1:$D$253,4,FALSE) -> BRN | B35: Brunei | C35: Sovereign
A36: =VLOOKUP(Table1[[#This Row],[Name]],'country codes'!$A$1:$D$253,4,FALSE) -> BGR | B36: Bulgaria | C36: Sovereign | D36: Y | E36: Y | F36: Y
A37: =VLOOKUP(Table1[[#This Row],[Name]],'country codes'!$A$1:$D$253,4,FALSE) -> BFA | B37: Burkina Faso | C37: Sovereign | D37: Y
A38: =VLOOKUP(Table1[[#This Row],[Name]],'country codes'!$A$1:$D$253,4,FALSE) -> BDI | B38: Burundi | C38: Sovereign | D38: Y | E38: Y
A39: =VLOOKUP(Table1[[#This Row],[Name]],'country codes'!$A$1:$D$253,4,FALSE) -> CPV | B39: Cabo Verde | C39: Sovereign
A40: =VLOOKUP(Table1[[#This Row],[Name]],'country codes'!$A$1:$D$253,4,FALSE) -> KHM | B40: Cambodia | C40: Sovereign | D40: Y | E40: Y | F40: Y | G40: Y
A41: =VLOOKUP(Table1[[#This Row],[Name]],'country codes'!$A$1:$D$253,4,FALSE) -> CMR | B41: Cameroon | C41: Sovereign | D41: Y
A42: =VLOOKUP(Table1[[#This Row],[Name]],'country codes'!$A$1:$D$253,4,FALSE) -> CAN | B42: Canada | C42: Sovereign | D42: Y | E42: Y | F42: Y | G42: Y
...

Sheet with years
D2: Chris | E2: Maggie | F2: Allyson | G2: Eddy
C3: Expanded list: | D3: =COUNTA(D7:D219) -> 140 | E3: =COUNTA(E7:E219) -> 134 | F3: =COUNTA(F7:F219) -> 69 | G3: =COUNTA(G7:G219) -> 60
C4: UN Member States only: | D4: =COUNTIFS($C$7:$C$219, "sovereign state", D7:D219, "<>") -> 125 | E4: =COUNTIFS($C$7:$C$219, "sovereign state", E7:E219, "<>") -> 116 | F4: =COUNTIFS($C$7:$C$219, "sovereign state", F7:F219, "<>") -> 62 | G4: =COUNTIFS($C$7:$C$219, "sovereign state", G7:G219, "<>") -> 54
A6: Code | B6: Country or Territory | C6: Political Status | D6: Chris | E6: Maggie | F6: Allyson | G6: Edward
A7: =VLOOKUP(B7,'country codes'!A2:B252,2,FALSE) -> AF | B7: Afghanistan | C7: Sovereign State | D7: 2018 | I7: Includes sovereign states and dependent territories
A8: =VLOOKUP(B8,'country codes'!A3:B253,2,FALSE) -> AL | B8: Albania | C8: Sovereign State | D8: 2017 | E8: 2017 | I8: Includes all countries entered, i.e., left the airport or seaport and went into town
A9: =VLOOKUP(B9,'country codes'!A4:B253,2,FALSE) -> DZ | B9: Algeria | C9: Sovereign State | I9: Excludes airport-only or port-only transit
A10: =VLOOKUP(B10,'country codes'!A5:B253,2,FALSE) -> AD | B10: Andorra | C10: Sovereign State
A11: =VLOOKUP(B11,'country codes'!A6:B253,2,FALSE) -> AO | B11: Angola | C11: Sovereign State | I11: **Note: there are a lot more dependent territories, only included those we've visited. Full list is on next sheet.
A12: =VLOOKUP(B12,'country codes'!A7:B254,2,FALSE) -> AG | B12: Antigua and Barbuda | C12: Sovereign State | D12: 2014 | E12: 2014 | F12: 2014 | G12: 2014
A13: =VLOOKUP(B13,'country codes'!A8:B255,2,FALSE) -> AR | B13: Argentina | C13: Sovereign State | D13: 2013 | E13: 2013 | F13: 2013 | G13: 2013 | I13: https://mtp.travel/users/me/checklists/locations/geographic/visited_remaining
A14: =VLOOKUP(B14,'country codes'!A9:B256,2,FALSE) -> AM | B14: Armenia | C14: Sovereign State | D14: 2021 | E14: 2021
A15: AW | B15: Aruba | C15: Constituent country of the Kingdom of the Netherlands | D15: 2014 | E15: 2014 | F15: 2014 | G15: 2014
A16: =VLOOKUP(B16,'country codes'!A10:B257,2,FALSE) -> AU | B16: Australia | C16: Sovereign State | D16: 2002 | E16: 2002 | F16: 2002 | G16: 2002
A17: =VLOOKUP(B17,'country codes'!A11:B258,2,FALSE) -> AT | B17: Austria | C17: Sovereign State | D17: 2016 | E17: 2016 | F17: 2016 | G17: 2016
A18: =VLOOKUP(B18,'country codes'!A12:B259,2,FALSE) -> AZ | B18: Azerbaijan | C18: Sovereign State | D18: 2021 | E18: 2021
A19: =VLOOKUP(B19,'country codes'!A14:B261,2,FALSE) -> BH | B19: Bahrain | C19: Sovereign State
A20: =VLOOKUP(B20,'country codes'!A15:B262,2,FALSE) -> BD | B20: Bangladesh | C20: Sovereign State
A21: =VLOOKUP(B21,'country codes'!A16:B263,2,FALSE) -> BB | B21: Barbados | C21: Sovereign State
A22: =VLOOKUP(B22,'country codes'!A18:B264,2,FALSE) -> BY | B22: Belarus | C22: Sovereign State
A23: =VLOOKUP(B23,'country codes'!A19:B265,2,FALSE) -> BE | B23: Belgium | C23: Sovereign State | D23: 1995 | E23: Y
A24: =VLOOKUP(B24,'country codes'!A21:B266,2,FALSE) -> BZ | B24: Belize | C24: Sovereign State | D24: 1997 | E24: Y
A25: =VLOOKUP(B25,'country codes'!A22:B267,2,FALSE) -> BJ | B25: Benin | C25: Sovereign State
A26: BM | B26: Bermuda | C26: Overseas territory of the United Kingdom
A27: =VLOOKUP(B27,'country codes'!A23:B268,2,FALSE) -> BT | B27: Bhutan | C27: Sovereign State
A28: =VLOOKUP(B28,'country codes'!A24:B269,2,FALSE) -> BO | B28: Bolivia | C28: Sovereign State | E28: Y
A29: =VLOOKUP(B29,'country codes'!A25:B270,2,FALSE) -> BA | B29: Bosnia and Herzegovina | C29: Sovereign State | D29: 2017 | E29: 2017
A30: =VLOOKUP(B30,'country codes'!A26:B271,2,FALSE) -> BW | B30: Botswana | C30: Sovereign State | D30: 2003 | E30: 2003 | F30: 2003 | G30: 2003
A31: =VLOOKUP(B31,'country codes'!A27:B272,2,FALSE) -> BR | B31: Brazil | C31: Sovereign State | D31: 2013 | E31: 2013 | F31: 2013 | G31: 2013
A32: =VLOOKUP(B32,'country codes'!A28:B273,2,FALSE) -> BN | B32: Brunei | C32: Sovereign State
A33: =VLOOKUP(B33,'country codes'!A29:B274,2,FALSE) -> BG | B33: Bulgaria | C33: Sovereign State | D33: 2019 | E33: 2019 | F33: 2019
A34: =VLOOKUP(B34,'country codes'!A30:B275,2,FALSE) -> BF | B34: Burkina Faso | C34: Sovereign State | D34: 1988
A35: =VLOOKUP(B35,'country codes'!A32:B277,2,FALSE) -> BI | B35: Burundi | C35: Sovereign State | D35: 1989 | E35: 1989
A36: =VLOOKUP(B36,'country codes'!A33:B278,2,FALSE) -> CV | B36: Cabo Verde | C36: Sovereign State
A37: =VLOOKUP(B37,'country codes'!A33:B279,2,FALSE) -> KH | B37: Cambodia | C37: Sovereign State | D37: 2010 | E37: 2010 | F37: 2010 | G37: 2010
A38: =VLOOKUP(B38,'country codes'!A34:B280,2,FALSE) -> CM | B38: Cameroon | C38: Sovereign State | D38: 1990
A39: =VLOOKUP(B39,'country codes'!A34:B281,2,FALSE) -> CA | B39: Canada | C39: Sovereign State | D39: 1980 | E39: 2024 | F39: 2024 | G39: 2024
A40: =VLOOKUP(B40,'country codes'!A35:B282,2,FALSE) -> IC | B40: Canary Islands | C40: Autonomous Community of Spain | D40: 2019 | E40: 2019 | F40: 2019 | G40: 2019
A41: KY | B41: Cayman Islands | C41: Crown dependency of the United Kingdom | D41: 2019 | E41: 2019 | F41: 2019 | G41: 2019
A42: =VLOOKUP(B42,'country codes'!A35:B282,2,FALSE) -> CF | B42: Central African Republic | C42: Sovereign State
...

Sheet U.S. States
B2: TOTALS: | C2: =COUNTA(C5:C212) -> 37 | D2: =COUNTA(D5:D212) -> 38
B3: US State | C3: Chris | D3: Maggie | F3: State Capital | K3: The Alaska cruise would give us AK and WA (and the Canadian Rockies!)
B4: Alabama | C4: Y | D4: Y | F4: Montgomery | K4: The Mississippi cruises hit Minnesota, Wisconsin, Iowa, Missouri, Tennessee, Mississippi, and Louisiana (they also pass Illinois and Arkansas, but those are not listed as stops).
B5: Alaska | C5: Y | D5: Y | F5: Juneau
B6: Arizona | C6: Y | D6: Y | F6: Phoenix | K6: So, we’ll have to do a road trip to the Heartland of America!
B7: Arkansas | C7: Y | F7: Little Rock | K7: West of Mississippi River for ND, NE, KS, OK, and AR.
B8: California | C8: Y | D8: Y | F8: Sacramento | K8: East of the Mississippi River for IL, IN, and KY.
B9: Colorado | C9: Y | D9: Y | F9: Denver | K9: New England to hit VT, ME, and NH.
B10: Connecticut | C10: Y | D10: Y | F10: Hartford | K10: And that would leave NM and OR. Could try to do OR in conjunction w/ Alaska Cruise.
B11: Delaware | C11: Y | D11: Y | F11: Dover | K11: Visiting the State capitals will probably be more interesting than visiting the large cities.
B12: Florida | C12: Y | D12: Y | F12: Tallahassee
B13: Georgia | C13: Y | D13: Y | F13: Atlanta
B14: Hawaii | C14: Y | D14: Y | F14: Honolulu
B15: Idaho | C15: Y | D15: Y | F15: Boise
B16: Illinois | D16: Y | F16: Springfield
B17: Indiana | C17: Y | F17: Indianapolis
B18: Iowa | C18: Y | F18: Des Moines
B19: Kansas | F19: Topeka
B20: Kentucky | F20: Frankfort
B21: Louisiana | C21: Y | F21: Baton Rouge
B22: Maine | C22: Y | F22: Augusta
B23: Maryland | C23: Y | D23: Y | F23: Annapolis
B24: Massachusetts | C24: Y | D24: Y | F24: Boston
B25: Michigan | C25: Y | D25: Y | F25: Lansing
B26: Minnesota | C26: Y | D26: Y | F26: St. Paul
B27: Mississippi | C27: Y | D27: Y | F27: Jackson
B28: Missouri | D28: Y | F28: Jefferson City
B29: Montana | C29: Y | D29: Y | F29: Helena
B30: Nebraska | F30: Lincoln
B31: Nevada | C31: Y | D31: Y | F31: Carson City
B32: New Hampshire | D32: Y | F32: Concord
B33: New Jersey | C33: Y | D33: Y | F33: Trenton
B34: New Mexico | D34: Y | F34: Santa Fe
B35: New York | C35: Y | D35: Y | F35: Albany
B36: North Carolina | C36: Y | D36: Y | F36: Raleigh
B37: North Dakota | F37: Bismarck
B38: Ohio | C38: Y | D38: Y | F38: Columbus
B39: Oklahoma | F39: Oklahoma City
B40: Oregon | D40: Y | F40: Salem
B41: Pennsylvania | C41: Y | D41: Y | F41: Harrisburg
...

Sheet fusion
A1: name | B1: code | C1: Chris | D1: Maggie | E1: Ally | F1: Eddy | G1: latitude | H1: longitude | I1: icon
A2: =VLOOKUP(B2,'Country or Territory'!A:G,2,FALSE) -> #N/A | B2: AF | C2: =IF(VLOOKUP(B2,'Country or Territory'!A:G,4,FALSE)="Y",$C$1 & " has visited","") -> #N/A | D2: =IF(VLOOKUP(B2,'Country or Territory'!A:G,5,FALSE)="Y",$D$1 & " has visited","") -> #N/A | E2: =IF(VLOOKUP(B2,'Country or Territory'!A:G,6,FALSE)="Y",$E$1 & " has visited","") -> #N/A | F2: =IF(VLOOKUP(B2,'Country or Territory'!A:G,7,FALSE)="Y",$F$1 & " has visited","") -> #N/A | G2: =VLOOKUP(B2,latlong!A:F,4,TRUE) -> 34.52813 | H2: =VLOOKUP(B2,latlong!A:F,5,TRUE) -> 69.17233 | I2: =4-COUNTBLANK(C2:F2) -> 4
A3: =VLOOKUP(B3,'Country or Territory'!A:G,2,FALSE) -> #N/A | B3: AL | C3: =IF(VLOOKUP(B3,'Country or Territory'!A:G,4,FALSE)="Y",$C$1 & " has visited","") -> #N/A | D3: =IF(VLOOKUP(B3,'Country or Territory'!A:G,5,FALSE)="Y",$D$1 & " has visited","") -> #N/A | E3: =IF(VLOOKUP(B3,'Country or Territory'!A:G,6,FALSE)="Y",$E$1 & " has visited","") -> #N/A | F3: =IF(VLOOKUP(B3,'Country or Territory'!A:G,7,FALSE)="Y",$F$1 & " has visited","") -> #N/A | G3: =VLOOKUP(B3,latlong!A:F,4,TRUE) -> 41.3275 | H3: =VLOOKUP(B3,latlong!A:F,5,TRUE) -> 19.81889 | I3: =4-COUNTBLANK(C3:F3) -> 4
A4: =VLOOKUP(B4,'Country or Territory'!A:G,2,FALSE) -> #N/A | B4: DZ | C4: =IF(VLOOKUP(B4,'Country or Territory'!A:G,4,FALSE)="Y",$C$1 & " has visited","") -> #N/A | D4: =IF(VLOOKUP(B4,'Country or Territory'!A:G,5,FALSE)="Y",$D$1 & " has visited","") -> #N/A | E4: =IF(VLOOKUP(B4,'Country or Territory'!A:G,6,FALSE)="Y",$E$1 & " has visited","") -> #N/A | F4: =IF(VLOOKUP(B4,'Country or Territory'!A:G,7,FALSE)="Y",$F$1 & " has visited","") -> #N/A | G4: =VLOOKUP(B4,latlong!A:F,4,TRUE) -> 36.7525 | H4: =VLOOKUP(B4,latlong!A:F,5,TRUE) -> 3.04197 | I4: =4-COUNTBLANK(C4:F4) -> 4
A5: =VLOOKUP(B5,'Country or Territory'!A:G,2,FALSE) -> #N/A | B5: AD | C5: =IF(VLOOKUP(B5,'Country or Territory'!A:G,4,FALSE)="Y",$C$1 & " has visited","") -> #N/A | D5: =IF(VLOOKUP(B5,'Country or Territory'!A:G,5,FALSE)="Y",$D$1 & " has visited","") -> #N/A | E5: =IF(VLOOKUP(B5,'Country or Territory'!A:G,6,FALSE)="Y",$E$1 & " has visited","") -> #N/A | F5: =IF(VLOOKUP(B5,'Country or Territory'!A:G,7,FALSE)="Y",$F$1 & " has visited","") -> #N/A | G5: =VLOOKUP(B5,latlong!A:F,4,TRUE) -> 42.50779 | H5: =VLOOKUP(B5,latlong!A:F,5,TRUE) -> 1.52109 | I5: =4-COUNTBLANK(C5:F5) -> 4
A6: =VLOOKUP(B6,'Country or Territory'!A:G,2,FALSE) -> #N/A | B6: AO | C6: =IF(VLOOKUP(B6,'Country or Territory'!A:G,4,FALSE)="Y",$C$1 & " has visited","") -> #N/A | D6: =IF(VLOOKUP(B6,'Country or Territory'!A:G,5,FALSE)="Y",$D$1 & " has visited","") -> #N/A | E6: =IF(VLOOKUP(B6,'Country or Territory'!A:G,6,FALSE)="Y",$E$1 & " has visited","") -> #N/A | F6: =IF(VLOOKUP(B6,'Country or Territory'!A:G,7,FALSE)="Y",$F$1 & " has visited","") -> #N/A | G6: =VLOOKUP(B6,latlong!A:F,4,TRUE) -> -8.83682 | H6: =VLOOKUP(B6,latlong!A:F,5,TRUE) -> 13.23432 | I6: =4-COUNTBLANK(C6:F6) -> 4
A7: =VLOOKUP(B7,'Country or Territory'!A:G,2,FALSE) -> #N/A | B7: AG | C7: =IF(VLOOKUP(B7,'Country or Territory'!A:G,4,FALSE)="Y",$C$1 & " has visited","") -> #N/A | D7: =IF(VLOOKUP(B7,'Country or Territory'!A:G,5,FALSE)="Y",$D$1 & " has visited","") -> #N/A | E7: =IF(VLOOKUP(B7,'Country or Territory'!A:G,6,FALSE)="Y",$E$1 & " has visited","") -> #N/A | F7: =IF(VLOOKUP(B7,'Country or Territory'!A:G,7,FALSE)="Y",$F$1 & " has visited","") -> #N/A | G7: =VLOOKUP(B7,latlong!A:F,4,TRUE) -> 17.11717 | H7: =VLOOKUP(B7,latlong!A:F,5,TRUE) -> -61.84573 | I7: =4-COUNTBLANK(C7:F7) -> 4
A8: =VLOOKUP(B8,'Country or Territory'!A:G,2,FALSE) -> #N/A | B8: AR | C8: =IF(VLOOKUP(B8,'Country or Territory'!A:G,4,FALSE)="Y",$C$1 & " has visited","") -> #N/A | D8: =IF(VLOOKUP(B8,'Country or Territory'!A:G,5,FALSE)="Y",$D$1 & " has visited","") -> #N/A | E8: =IF(VLOOKUP(B8,'Country or Territory'!A:G,6,FALSE)="Y",$E$1 & " has visited","") -> #N/A | F8: =IF(VLOOKUP(B8,'Country or Territory'!A:G,7,FALSE)="Y",$F$1 & " has visited","") -> #N/A | G8: =VLOOKUP(B8,latlong!A:F,4,TRUE) -> -34.61315 | H8: =VLOOKUP(B8,latlong!A:F,5,TRUE) -> -58.37723 | I8: =4-COUNTBLANK(C8:F8) -> 4
A9: =VLOOKUP(B9,'Country or Territory'!A:G,2,FALSE) -> #N/A | B9: AM | C9: =IF(VLOOKUP(B9,'Country or Territory'!A:G,4,FALSE)="Y",$C$1 & " has visited","") -> #N/A | D9: =IF(VLOOKUP(B9,'Country or Territory'!A:G,5,FALSE)="Y",$D$1 & " has visited","") -> #N/A | E9: =IF(VLOOKUP(B9,'Country or Territory'!A:G,6,FALSE)="Y",$E$1 & " has visited","") -> #N/A | F9: =IF(VLOOKUP(B9,'Country or Territory'!A:G,7,FALSE)="Y",$F$1 & " has visited","") -> #N/A | G9: =VLOOKUP(B9,latlong!A:F,4,TRUE) -> 40.18111 | H9: =VLOOKUP(B9,latlong!A:F,5,TRUE) -> 44.51361 | I9: =4-COUNTBLANK(C9:F9) -> 4
A10: =VLOOKUP(B10,'Country or Territory'!A:G,2,FALSE) -> #N/A | B10: AU | C10: =IF(VLOOKUP(B10,'Country or Territory'!A:G,4,FALSE)="Y",$C$1 & " has visited","") -> #N/A | D10: =IF(VLOOKUP(B10,'Country or Territory'!A:G,5,FALSE)="Y",$D$1 & " has visited","") -> #N/A | E10: =IF(VLOOKUP(B10,'Country or Territory'!A:G,6,FALSE)="Y",$E$1 & " has visited","") -> #N/A | F10: =IF(VLOOKUP(B10,'Country or Territory'!A:G,7,FALSE)="Y",$F$1 & " has visited","") -> #N/A | G10: =VLOOKUP(B10,latlong!A:F,4,TRUE) -> -33.86785 | H10: =VLOOKUP(B10,latlong!A:F,5,TRUE) -> 151.20732 | I10: =4-COUNTBLANK(C10:F10) -> 4
A11: =VLOOKUP(B11,'Country or Territory'!A:G,2,FALSE) -> #N/A | B11: AT | C11: =IF(VLOOKUP(B11,'Country or Territory'!A:G,4,FALSE)="Y",$C$1 & " has visited","") -> #N/A | D11: =IF(VLOOKUP(B11,'Country or Territory'!A:G,5,FALSE)="Y",$D$1 & " has visited","") -> #N/A | E11: =IF(VLOOKUP(B11,'Country or Territory'!A:G,6,FALSE)="Y",$E$1 & " has visited","") -> #N/A | F11: =IF(VLOOKUP(B11,'Country or Territory'!A:G,7,FALSE)="Y",$F$1 & " has visited","") -> #N/A | G11: =VLOOKUP(B11,latlong!A:F,4,TRUE) -> 48.20849 | H11: =VLOOKUP(B11,latlong!A:F,5,TRUE) -> 16.37208 | I11: =4-COUNTBLANK(C11:F11) -> 4
A12: =VLOOKUP(B12,'Country or Territory'!A:G,2,FALSE) -> #N/A | B12: AZ | C12: =IF(VLOOKUP(B12,'Country or Territory'!A:G,4,FALSE)="Y",$C$1 & " has visited","") -> #N/A | D12: =IF(VLOOKUP(B12,'Country or Territory'!A:G,5,FALSE)="Y",$D$1 & " has visited","") -> #N/A | E12: =IF(VLOOKUP(B12,'Country or Territory'!A:G,6,FALSE)="Y",$E$1 & " has visited","") -> #N/A | F12: =IF(VLOOKUP(B12,'Country or Territory'!A:G,7,FALSE)="Y",$F$1 & " has visited","") -> #N/A | G12: =VLOOKUP(B12,latlong!A:F,4,TRUE) -> 40.37767 | H12: =VLOOKUP(B12,latlong!A:F,5,TRUE) -> 49.89201 | I12: =4-COUNTBLANK(C12:F12) -> 4
A13: =VLOOKUP(B13,'Country or Territory'!A:G,2,FALSE) -> #N/A | B13: BS | C13: =IF(VLOOKUP(B13,'Country or Territory'!A:G,4,FALSE)="Y",$C$1 & " has visited","") -> #N/A | D13: =IF(VLOOKUP(B13,'Country or Territory'!A:G,5,FALSE)="Y",$D$1 & " has visited","") -> #N/A | E13: =IF(VLOOKUP(B13,'Country or Territory'!A:G,6,FALSE)="Y",$E$1 & " has visited","") -> #N/A | F13: =IF(VLOOKUP(B13,'Country or Territory'!A:G,7,FALSE)="Y",$F$1 & " has visited","") -> #N/A | G13: =VLOOKUP(B13,latlong!A:F,4,TRUE) -> 25.05823 | H13: =VLOOKUP(B13,latlong!A:F,5,TRUE) -> -77.34306 | I13: =4-COUNTBLANK(C13:F13) -> 4
... A198: =VLOOKUP(B198,'Country or Territory'!A:G,2,FALSE) -> #N/A | B198: GI | C198: =IF(VLOOKUP(B198,'Country or Territory'!A:G,4,FALSE)="Y",$C$1 & " has visited","") -> #N/A | D198: =IF(VLOOKUP(B198,'Country or Territory'!A:G,5,FALSE)="Y",$D$1 & " has visited","") -> #N/A | E198: =IF(VLOOKUP(B198,'Country or Territory'!A:G,6,FALSE)="Y",$E$1 & " has visited","") -> #N/A | F198: =IF(VLOOKUP(B198,'Country or Territory'!A:G,7,FALSE)="Y",$F$1 & " has visited","") -> #N/A | G198: =VLOOKUP(B198,latlong!A:F,4,TRUE) -> 36.14474 | H198: =VLOOKUP(B198,latlong!A:F,5,TRUE) -> -5.35257 | I198: =4-COUNTBLANK(C198:F198) -> 4

Sheet Sovereign & Non-Sovereign
B2: Sovereign states and dependent territories | J2: ISO 3166 standard defining codes for the names of countries, dependent territories, and special areas of geographical interest.
B3: https://en.wikipedia.org/wiki/List_of_sovereign_states_and_dependent_territories_by_continent | J3: https://en.wikipedia.org/wiki/ISO_3166-1
B4: Classification according to United Nations Statistics Division geoscheme, for statistical purposes
B5: excluding minor dependent territories that are not travel/tourism destinations
B6: Non-sovereign or dependent territories are:
B7: 1. Integral parts of sovereign states located outside these states' mainland.
B8: 2. Dependent territories of sovereign states.
B9: 3. Special territories recognized by international treaty (such as the special administrative regions of China)
B10: 4. Other territories often regarded as separate geographical territories even though they are integral parts of their mother countries (such as the overseas departments of France)
H12: Xinjiang SAR
B13: Name | C13: Capital | D13: Status
B14: Åland Islands | C14: Mariehamn | D14: Autonomous region of Finland (recognized by international treaty)
B15: Aruba | C15: Oranjestad | D15: Constituent country of the Kingdom of the Netherlands
B16: Curaçao | C16: Willemstad | D16: Constituent country of the Kingdom of the Netherlands
B17: Sint Maarten | C17: Philipsburg | D17: Constituent country of the Kingdom of the Netherlands
B18: Guernsey | C18: Saint Peter Port | D18: Crown dependency of the United Kingdom
B19: Isle of Man | C19: Douglas | D19: Crown dependency of the United Kingdom
B20: Jersey | C20: Saint Helier | D20: Crown dependency of the United Kingdom
B21: Sahrawi Arab Democratic Republic | C21: El Aaiún (official) | D21: De facto sovereign state lacking general international recognition. Claims territory of Western Sahara, most of which is controlled by Morocco.
B22: Nagorno-Karabakh | C22: Stepanakert | D22: De facto sovereign state lacking general international recognition. Recognized by the United Nations as part of Azerbaijan.
B23: Taiwan | C23: Taipei | D23: De facto sovereign state lacking general international recognition. Recognized by the United Nations as part of China.
B24: Northern Cyprus | C24: Nicosia | D24: De facto sovereign state lacking general international recognition. Recognized by the United Nations as part of Cyprus.
... B87: New Caledonia | C87: Nouméa | D87: Sui generis collectivity (special collectivity) of France
B89: Afghanistan | C89: Kabul
B90: Albania | C90: Tirana
B91: Algeria | C91: Algiers
B92: Andorra | C92: Andorra la Vella
B93: Angola | C93: Luanda
B94: Antigua and Barbuda | C94: St. John's
B95: Argentina | C95: Buenos Aires
B96: Armenia [Europe] | C96: Yerevan
B97: Australia | C97: Canberra
B98: Austria | C98: Vienna
B99: Azerbaijan [Europe] | C99: Baku
B100: Bahamas | C100: Nassau
... B284: Zimbabwe | C284: Harare

Sheet country codes
A1: NAME | B1: alpha 2 | C1: alpha 3 | D1: ADM0_A3 | E1: ISO 3166-2 | F1: reference code
A2: Afghanistan | B2: AF | C2: AFG | D2: =VLOOKUP(A2,'geojson fields'!$A$1:$M$280,12, FALSE) -> AFG | F2: =IF(ISBLANK(E2),B2,E2) -> AF
A3: Aland | B3: AX | C3: ALA | D3: =VLOOKUP(A3,'geojson fields'!$A$1:$M$280,12, FALSE) -> ALD | F3: =IF(ISBLANK(E3),B3,E3) -> AX
A4: Albania | B4: AL | C4: ALB | D4: =VLOOKUP(A4,'geojson fields'!$A$1:$M$280,12, FALSE) -> ALB | F4: =IF(ISBLANK(E4),B4,E4) -> AL
A5: Algeria | B5: DZ | C5: DZA | D5: =VLOOKUP(A5,'geojson fields'!$A$1:$M$280,12, FALSE) -> DZA | F5: =IF(ISBLANK(E5),B5,E5) -> DZ
A6: American Samoa | B6: AS | C6: ASM | D6: =VLOOKUP(A6,'geojson fields'!$A$1:$M$280,12, FALSE) -> ASM | F6: =IF(ISBLANK(E6),B6,E6) -> AS
A7: Andorra | B7: AD | C7: AND | D7: =VLOOKUP(A7,'geojson fields'!$A$1:$M$280,12, FALSE) -> AND | F7: =IF(ISBLANK(E7),B7,E7) -> AD
A8: Angola | B8: AO | C8: AGO | D8: =VLOOKUP(A8,'geojson fields'!$A$1:$M$280,12, FALSE) -> AGO | F8: =IF(ISBLANK(E8),B8,E8) -> AO
A9: Anguilla | B9: AI | C9: AIA | D9: =VLOOKUP(A9,'geojson fields'!$A$1:$M$280,12, FALSE) -> AIA | F9: =IF(ISBLANK(E9),B9,E9) -> AI
A10: Antarctica | B10: AQ | C10: ATA | D10: =VLOOKUP(A10,'geojson fields'!$A$1:$M$280,12, FALSE) -> ATA | F10: =IF(ISBLANK(E10),B10,E10) -> AQ
A11: Antigua and Barbuda | B11: AG | C11: ATG | D11: =VLOOKUP(A11,'geojson fields'!$A$1:$M$280,12, FALSE) -> ATG | F11: =IF(ISBLANK(E11),B11,E11) -> AG
A12: Argentina | B12: AR | C12: ARG | D12: =VLOOKUP(A12,'geojson fields'!$A$1:$M$280,12, FALSE) -> ARG | F12: =IF(ISBLANK(E12),B12,E12) -> AR
A13: Armenia | B13: AM | C13: ARM | D13: =VLOOKUP(A13,'geojson fields'!$A$1:$M$280,12, FALSE) -> ARM | F13: =IF(ISBLANK(E13),B13,E13) -> AM
... A17: Azerbaijan | B17: AZ | C17: AZE | D17: =VLOOKUP(A17,'geojson fields'!$A$1:$M$280,12, FALSE) -> AZE | F17: =IF(ISBLANK(E17),B17,E17) -> AZ
A18: Azores | D18: =VLOOKUP(A18,'geojson fields'!$A$1:$M$280,12, FALSE) -> PT-20 | E18: PT-20 | F18: =IF(ISBLANK(E18),B18,E18) -> PT-20
A19: Bahamas | B19: BS | C19: BHS | D19: =VLOOKUP(A19,'geojson fields'!$A$1:$M$280,12, FALSE) -> BHS | F19: =IF(ISBLANK(E19),B19,E19) -> BS
A20: Bahrain | B20: BH | C20: BHR | D20: =VLOOKUP(A20,'geojson fields'!$A$1:$M$280,12, FALSE) -> BHR | F20: =IF(ISBLANK(E20),B20,E20) -> BH
A21: Baleares | D21: =VLOOKUP(A21,'geojson fields'!$A$1:$M$280,12, FALSE) -> ES-PM | E21: ES-PM
A22: Bangladesh | B22: BD | C22: BGD | D22: =VLOOKUP(A22,'geojson fields'!$A$1:$M$280,12, FALSE) -> BGD | F22: =IF(ISBLANK(E22),B22,E22) -> BD
A23: Barbados | B23: BB | C23: BRB | D23: =VLOOKUP(A23,'geojson fields'!$A$1:$M$280,12, FALSE) -> BRB | F23: =IF(ISBLANK(E23),B23,E23) -> BB
A24: Belarus | B24: BY | C24: BLR | D24: =VLOOKUP(A24,'geojson fields'!$A$1:$M$280,12, FALSE) -> BLR | F24: =IF(ISBLANK(E24),B24,E24) -> BY
A25: Belgium | B25: BE | C25: BEL | D25: =VLOOKUP(A25,'geojson fields'!$A$1:$M$280,12, FALSE) -> BEL | F25: =IF(ISBLANK(E25),B25,E25) -> BE
A26: Belize | B26: BZ | C26: BLZ | D26: =VLOOKUP(A26,'geojson fields'!$A$1:$M$280,12, FALSE) -> BLZ | F26: =IF(ISBLANK(E26),B26,E26) -> BZ
A27: Benin | B27: BJ | C27: BEN | D27: =VLOOKUP(A27,'geojson fields'!$A$1:$M$280,12, FALSE) -> BEN | F27: =IF(ISBLANK(E27),B27,E27) -> BJ
A28: Bermuda | B28: BM | C28: BMU | D28: =VLOOKUP(A28,'geojson fields'!$A$1:$M$280,12, FALSE) -> BMU | F28: =IF(ISBLANK(E28),B28,E28) -> BM
A29: Bhutan | B29: BT | C29: BTN | D29: =VLOOKUP(A29,'geojson fields'!$A$1:$M$280,12, FALSE) -> BTN | F29: =IF(ISBLANK(E29),B29,E29) -> BT
A30: Bolivia | B30: BO | C30: BOL | D30: =VLOOKUP(A30,'geojson fields'!$A$1:$M$280,12, FALSE) -> BOL | F30: =IF(ISBLANK(E30),B30,E30) -> BO
A31: Bonaire | B31: BQ | C31: BES | D31: =VLOOKUP(A31,'geojson fields'!$A$1:$M$280,12, FALSE) -> NL-BQ1 | F31: =IF(ISBLANK(E31),B31,E31) -> BQ
A32: Bosnia and Herzegovina | B32: BA | C32: BIH | D32: =VLOOKUP(A32,'geojson fields'!$A$1:$M$280,12, FALSE) -> BIH | F32: =IF(ISBLANK(E32),B32,E32) -> BA
A33: Botswana | B33: BW | C33: BWA | D33: =VLOOKUP(A33,'geojson fields'!$A$1:$M$280,12, FALSE) -> BWA | F33: =IF(ISBLANK(E33),B33,E33) -> BW
... A43: Canada | B43: CA | C43: CAN | D43: =VLOOKUP(A43,'geojson fields'!$A$1:$M$280,12, FALSE) -> CAN | F43: =IF(ISBLANK(E43),B43,E43) -> CA
A44: Canary Islands | B44: IC | D44: =VLOOKUP(A44,'geojson fields'!$A$1:$M$280,12, FALSE) -> ES-CN | E44: ES-CN | F44: =IF(ISBLANK(E44),B44,E44) -> ES-CN
A45: Cayman Islands | B45: KY | C45: CYM | D45: =VLOOKUP(A45,'geojson fields'!$A$1:$M$280,12, FALSE) -> CYM | F45: =IF(ISBLANK(E45),B45,E45) -> KY
A46: Central African Republic | B46: CF | C46: CAF | D46: =VLOOKUP(A46,'geojson fields'!$A$1:$M$280,12, FALSE) -> CAF | F46: =IF(ISBLANK(E46),B46,E46) -> CF
A47: Ceuta | D47: =VLOOKUP(A47,'geojson fields'!$A$1:$M$280,12, FALSE) -> ES-CE | E47: ES-CE | F47: =IF(ISBLANK(E47),B47,E47) -> ES-CE
A48: Chad | B48: TD | C48: TCD | D48: =VLOOKUP(A48,'geojson fields'!$A$1:$M$280,12, FALSE) -> TCD | F48: =IF(ISBLANK(E48),B48,E48) -> TD
A49: Chile | B49: CL | C49: CHL | D49: =VLOOKUP(A49,'geojson fields'!$A$1:$M$280,12, FALSE) -> CHL | F49: =IF(ISBLANK(E49),B49,E49) -> CL
A50: China | B50: CN | C50: CHN | D50: =VLOOKUP(A50,'geojson fields'!$A$1:$M$280,12, FALSE) -> CHN | F50: =IF(ISBLANK(E50),B50,E50) -> CN
A51: Clipperton Island | D51: =VLOOKUP(A51,'geojson fields'!$A$1:$M$280,12, FALSE) -> CLP
A52: Colombia | B52: CO | C52: COL | D52: =VLOOKUP(A52,'geojson fields'!$A$1:$M$280,12, FALSE) -> COL | F52: =IF(ISBLANK(E52),B52,E52) -> CO
...

Sheet geojson fields
A1: NAME | B1: featurecla | C1: scalerank | D1: LABELRANK | E1: SOVEREIGNT | F1: SOV_A3 | G1: ADM0_DIF | H1: LEVEL | I1: TYPE | J1: TLC | K1: ADMIN | L1: ADM0_A3 | M1: GEOU_DIF | N1: GEOUNIT | O1: GU_A3 | P1: SU_DIF | Q1: SUBUNIT | R1: SU_A3 | S1: BRK_DIFF | T1: NAME_LONG | U1: BRK_A3 | V1: BRK_NAME | W1: BRK_GROUP | X1: ABBREV | Y1: POSTAL | Z1: FORMAL_EN | AA1: FORMAL_FR | AB1: NAME_CIAWF | AC1: NOTE_ADM0 | AD1: NOTE_BRK | AE1: NAME_SORT | AF1: NAME_ALT | AG1: MAPCOLOR7 | AH1: MAPCOLOR8 | AI1: MAPCOLOR9 | AJ1: MAPCOLOR13 | AK1: POP_EST | AL1: POP_RANK | AM1: POP_YEAR | AN1: GDP_MD | AO1: GDP_YEAR | AP1: ECONOMY | AQ1: INCOME_GRP | AR1: FIPS_10 | AS1: ISO_A2 | AT1: ISO_A2_EH | AU1: ISO_A3 | AV1: ISO_A3_EH | AW1: ISO_N3 | AX1: ISO_N3_EH | AY1: UN_A3 | AZ1: WB_A2 | BA1: WB_A3 | BB1: WOE_ID | BC1: WOE_ID_EH | BD1: WOE_NOTE | BE1: ADM0_ISO | BF1: ADM0_DIFF | BG1: ADM0_TLC | BH1: ADM0_A3_US | BI1: ADM0_A3_FR | BJ1: ADM0_A3_RU | BK1: ADM0_A3_ES | BL1: ADM0_A3_CN | BM1: ADM0_A3_TW | BN1: ADM0_A3_IN | BO1: ADM0_A3_NP | BP1: ADM0_A3_PK | BQ1: ADM0_A3_DE | BR1: ADM0_A3_GB | BS1: ADM0_A3_BR | BT1: ADM0_A3_IL | BU1: ADM0_A3_PS | BV1: ADM0_A3_SA | BW1: ADM0_A3_EG | BX1: ADM0_A3_MA | BY1: ADM0_A3_PT | BZ1: ADM0_A3_AR | CA1: ADM0_A3_JP | CB1: ADM0_A3_KO | CC1: ADM0_A3_VN | CD1: ADM0_A3_TR | CE1: ADM0_A3_ID | CF1: ADM0_A3_PL | CG1: ADM0_A3_GR | CH1: ADM0_A3_IT | CI1: ADM0_A3_NL | CJ1: ADM0_A3_SE | CK1: ADM0_A3_BD | CL1: ADM0_A3_UA | CM1: ADM0_A3_UN | CN1: ADM0_A3_WB | CO1: CONTINENT | CP1: REGION_UN | CQ1: SUBREGION | CR1: REGION_WB | CS1: NAME_LEN | CT1: LONG_LEN | CU1: ABBREV_LEN | CV1: TINY | CW1: HOMEPART | CX1: MIN_ZOOM | CY1: MIN_LABEL | CZ1: MAX_LABEL | DA1: LABEL_X | DB1: LABEL_Y | DC1: NE_ID | DD1: WIKIDATAID | DE1: NAME_AR | DF1: NAME_BN | DG1: NAME_DE | DH1: NAME_EN | DI1: NAME_ES | DJ1: NAME_FA | DK1: NAME_FR | DL1: NAME_EL | DM1: NAME_HE | DN1: NAME_HI | DO1: NAME_HU | DP1: NAME_ID | DQ1: NAME_IT | DR1: NAME_JA | DS1: NAME_KO | DT1: NAME_NL | DU1: NAME_PL | DV1: NAME_PT | DW1: NAME_RU | DX1: NAME_SV | DY1: NAME_TR | DZ1: NAME_UK | EA1: NAME_UR | EB1: NAME_VI | EC1: NAME_ZH | ED1: NAME_ZHT | EE1: FCLASS_ISO | EF1: TLC_DIFF | EG1: FCLASS_TLC | EH1: FCLASS_US | EI1: FCLASS_FR | EJ1: FCLASS_RU | EK1: FCLASS_ES | EL1: FCLASS_CN | EM1: FCLASS_TW | EN1: FCLASS_IN | EO1: FCLASS_NP | EP1: FCLASS_PK | EQ1: FCLASS_DE | ER1: FCLASS_GB | ES1: FCLASS_BR | ET1: FCLASS_IL | EU1: FCLASS_PS | EV1: FCLASS_SA | EW1: FCLASS_EG | EX1: FCLASS_MA | EY1: FCLASS_PT | EZ1: FCLASS_AR | FA1: FCLASS_JP | FB1: FCLASS_KO | FC1: FCLASS_VN | FD1: FCLASS_TR | FE1: FCLASS_ID | FF1: FCLASS_PL | FG1: FCLASS_GR | FH1: FCLASS_IT | FI1: FCLASS_NL | FJ1: FCLASS_SE | FK1: FCLASS_BD | FL1: FCLASS_UA | FM1: iso_3166_2 | FN1: adm1_code | FO1: diss_me | FP1: wikipedia | FQ1: iso_a2 | FR1: adm0_sr | FS1: name_alt | FT1: name_local | FU1: type | FV1: type_en | FW1: code_local | FX1: code_hasc | FY1: note | FZ1: hasc_maybe | GA1: region | GB1: provnum_ne | GC1: gadm_level | GD1: check_me | GE1: datarank | GF1: abbrev | GG1: postal | GH1: area_sqkm | GI1: sameascity | GJ1: labelrank | GK1: name_len | GL1: mapcolor9 | GM1: mapcolor13 | GN1: fips | GO1: fips_alt | GP1: woe_id | GQ1: woe_label | GR1: woe_name | GS1: latitude | GT1: longitude | GU1: sov_a3 | GV1: adm0_a3 | GW1: adm0_label | GX1: admin | GY1: geonunit | GZ1: gu_a3 | HA1: gn_id | HB1: gn_name | HC1: gns_id | HD1: gns_name | HE1: gn_level | HF1: gn_region | HG1: gn_a1_code | HH1: region_sub | HI1: sub_code | HJ1: gns_level | HK1: gns_lang | HL1: gns_adm1 | HM1: gns_region | HN1: min_label | HO1: max_label | HP1: min_zoom | HQ1: wikidataid | HR1: name_ar | HS1: name_bn | HT1: name_de | HU1: name_en | HV1: name_es | HW1: name_fr | HX1: name_el | HY1: name_hi | HZ1: name_hu | IA1: name_id | IB1: name_it | IC1: name_ja | ID1: name_ko | IE1: name_nl | IF1: name_pl | IG1: name_pt | IH1: name_ru | II1: name_sv | IJ1: name_tr | IK1: name_vi | IL1: name_zh | IM1: ne_id | IN1: name_he | IO1: name_uk | IP1: name_ur | IQ1: name_fa | IR1: name_zht | IS1: region_cod
A2: Afghanistan | B2: Admin-0 country | C2: 0 | D2: 3 | E2: Afghanistan | F2: AFG | G2: 0 | H2: 2 | I2: Sovereign country | J2: 1 | K2: Afghanistan | L2: AFG | M2: 0 | N2: Afghanistan | O2: AFG | P2: 0 | Q2: Afghanistan | R2: AFG | S2: 0 | T2: Afghanistan | U2: AFG | V2: Afghanistan | X2: Afg. | Y2: AF | Z2: Islamic State of Afghanistan | AB2: Afghanistan | AE2: Afghanistan | AG2: 5 | AH2: 6 | AI2: 8 | AJ2: 7 | AK2: 38041754 | AL2: 15 | AM2: 2019 | AN2: 19291 | AO2: 2019 | AP2: 7. Least developed region | AQ2: 5. Low income | AR2: AF | AS2: AF | AT2: AF | AU2: AFG | AV2: AFG | AW2: 4 | AX2: 4 | AY2: 4 | AZ2: AF | BA2: AFG | BB2: 23424739 | BC2: 23424739 | BD2: Exact WOE match as country | BE2: AFG | BG2: AFG | BH2: AFG | BI2: AFG | BJ2: AFG | BK2: AFG | BL2: AFG | BM2: AFG | BN2: AFG | BO2: AFG | BP2: AFG | BQ2: AFG | BR2: AFG | BS2: AFG | BT2: AFG | BU2: AFG | BV2: AFG | BW2: AFG | BX2: AFG | BY2: AFG | BZ2: AFG | CA2: AFG | CB2: AFG | CC2: AFG | CD2: AFG | CE2: AFG | CF2: AFG | CG2: AFG | CH2: AFG | CI2: AFG | CJ2: AFG | CK2: AFG | CL2: AFG | CM2: -99 | CN2: -99 | CO2: Asia | CP2: Asia | CQ2: Southern Asia | CR2: South Asia | CS2: 11 | CT2: 11 | CU2: 4 | CV2: -99 | CW2: 1 | CX2: 0 | CY2: 3 | CZ2: 7 | DA2: 66.496586 | DB2: 34.164262 | DC2: 1159320319 | DD2: Q889 | DE2: Ø£ÙØºØ§Ù†Ø³ØªØ§Ù† | DF2: à¦†à¦«à¦—à¦¾à¦¨à¦¿à¦¸à§à¦¤à¦¾à¦¨ | DG2: Afghanistan | DH2: Afghanistan | DI2: AfganistÃ¡n | DJ2: Ø§ÙØºØ§Ù†Ø³ØªØ§Ù† | DK2: Afghanistan | DL2: Î‘Ï†Î³Î±Î½Î¹ÏƒÏ„Î¬Î½ | DM2: ××¤×’× ×™×¡×˜×Ÿ | DN2: à¤…à¤«à¤¼à¥à¤—à¤¾à¤¨à¤¿à¤¸à¥à¤¤à¤¾à¤¨ | DO2: AfganisztÃ¡n | DP2: Afganistan | DQ2: Afghanistan | DR2: ã‚¢ãƒ•ã‚¬ãƒ‹ã‚¹ã‚¿ãƒ³ | DS2: ì•„í”„ê°€ë‹ˆìŠ¤íƒ„ | DT2: Afghanistan | DU2: Afganistan | DV2: AfeganistÃ£o | DW2: ÐÑ„Ð³Ð°Ð½Ð¸ÑÑ‚Ð°Ð½ | DX2: Afghanistan | DY2: Afganistan | DZ2: ÐÑ„Ð³Ð°Ð½Ñ–ÑÑ‚Ð°Ð½ | EA2: Ø§ÙØºØ§Ù†Ø³ØªØ§Ù† | EB2: Afghanistan | EC2: é˜¿å¯Œæ±— | ED2: é˜¿å¯Œæ±— | EE2: Admin-0 country | EG2: Admin-0 country
A3: Akrotiri | B3: Admin-0 country | C3: 3 | D3: 3 | E3: United Kingdom | F3: GB1 | G3: 1 | H3: 2 | I3: Dependency | J3: 1 | K3: Akrotiri Sovereign Base Area | L3: WSB | M3: 0 | N3: Akrotiri Sovereign Base Area | O3: WSB | P3: 0 | Q3: Akrotiri Sovereign Base Area | R3: WSB | S3: 0 | T3: Akrotiri | U3: WSB | V3: Akrotiri | X3: Akr. | Y3: AK | AC3: U.K. | AD3: U.K. Base | AE3: Akrotiri Sovereign Base Area | AG3: 6 | AH3: 6 | AI3: 6 | AJ3: 3 | AK3: 7850 | AL3: 5 | AM3: 2017 | AN3: 314 | AO3: 2016 | AP3: 2. Developed region: nonG7 | AQ3: 2. High income: nonOECD | AR3: -99 | AS3: -99 | AT3: -99 | AU3: -99 | AV3: -99 | AW3: -99 | AX3: -99 | AY3: -99 | AZ3: -99 | BA3: -99 | BB3: -99 | BC3: -99 | BD3: No WOE equivalent. | BE3: -99 | BF3: 1 | BG3: WSB | BH3: WSB | BI3: WSB | BJ3: WSB | BK3: WSB | BL3: WSB | BM3: WSB | BN3: WSB | BO3: WSB | BP3: WSB | BQ3: WSB | BR3: WSB | BS3: WSB | BT3: WSB | BU3: WSB | BV3: WSB | BW3: WSB | BX3: WSB | BY3: WSB | BZ3: WSB | CA3: WSB | CB3: WSB | CC3: WSB | CD3: WSB | CE3: WSB | CF3: WSB | CG3: WSB | CH3: WSB | CI3: WSB | CJ3: WSB | CK3: WSB | CL3: WSB | CM3: -99 | CN3: -99 | CO3: Asia | CP3: Asia | CQ3: Western Asia | CR3: Europe & Central Asia | CS3: 8 | CT3: 8 | CU3: 4 | CV3: -99 | CW3: -99 | CX3: 0 | CY3: 6.5 | CZ3: 11 | DA3: 32.979025 | DB3: 34.60083 | DC3: 1159320741 | DD3: Q9143535 | DE3: Ø£ÙƒØ±ÙˆØªÙŠØ±ÙŠ | DF3: à¦†à¦•à§à¦°à§‹à¦¤à¦¿à¦°à¦¿ | DG3: Akrotiri | DH3: Akrotiri Sovereign Base Area | DI3: Akrotiri | DJ3: Ø¢Ú©Ø±ÙˆØªÛŒÛŒØ±ÛŒ | DK3: Akrotiri | DL3: Î”Ï…Ï„Î¹ÎºÎ® Î ÎµÏÎ¹Î¿Ï‡Î® ÎšÏ…ÏÎ¯Î±ÏÏ‡Ï‰Î½ Î’Î¬ÏƒÎµÏ‰Î½ | DM3: ××§×¨×•×˜×™×¨×™ | DN3: à¤…à¤•à¥à¤°à¥‹à¤¤à¤¿à¤°à¥€ | DO3: AkrotÃ­ri | DP3: Akrotiri | DQ3: Akrotiri | DR3: ã‚¢ã‚¯ãƒ­ãƒ†ã‚£ãƒª | DS3: ì•„í¬ë¡œí‹°ë¦¬ | DT3: Akrotiri | DU3: Akrotiri | DV3: AcrotÃ­ri | DW3: ÐÐºÑ€Ð¾Ñ‚Ð¸Ñ€Ð¸ | DX3: Akrotiri | DY3: AÄŸrotur | DZ3: ÐÐºÑ€Ð¾Ñ‚Ñ–Ñ€Ñ– | EA3: Ø§ÛŒÚ©Ø±ÙˆÙ¹ÛŒØ±ÛŒ | EB3: Akrotiri | EC3: é˜¿å…‹ç½—è’‚é‡Œä¸»æƒåŸºåœ°åŒº | ED3: é˜¿å…‹ç½—è’‚é‡Œä¸»æƒåŸºåœ°åŒº | EE3: Unrecognized | EF3: 1 | EG3: Admin-0 dependency | EH3: Admin-0 dependency | EI3: Admin-0 dependency | EK3: Admin-0 dependency | EQ3: Admin-0 dependency | ER3: Admin-0 dependency | EY3: Admin-0 dependency | FA3: Admin-0 dependency | FB3: Admin-0 dependency | FD3: Admin-0 dependency | FF3: Admin-0 dependency | FG3: Admin-0 dependency | FH3: Admin-0 dependency | FI3: Admin-0 dependency | FJ3: Admin-0 dependency | FL3: Admin-0 dependency
A4: Aland | B4: Admin-0 country | C4: 3 | D4: 6 | E4: Finland | F4: FI1 | G4: 1 | H4: 2 | I4: Country | J4: 1 | K4: Aland | L4: ALD | M4: 0 | N4: Aland | O4: ALD | P4: 0 | Q4: Aland | R4: ALD | S4: 0 | T4: Ã…land Islands | U4: ALD | V4: Ã…land | X4: Ã…land | Y4: AI | Z4: Ã…land Islands | AC4: Fin. | AE4: Aland | AG4: 4 | AH4: 1 | AI4: 4 | AJ4: 6 | AK4: 29884 | AL4: 7 | AM4: 2019 | AN4: 1563 | AO4: 2016 | AP4: 2. Developed region: nonG7 | AQ4: 1. High income: OECD | AR4: -99 | AS4: AX | AT4: AX | AU4: ALA | AV4: ALA | AW4: 248 | AX4: 248 | AY4: 248 | AZ4: -99 | BA4: -99 | BB4: 12577865 | BC4: 12577865 | BD4: Exact WOE match as country | BE4: ALD | BG4: ALD | BH4: ALD | BI4: ALD | BJ4: ALD | BK4: ALD | BL4: ALD | BM4: ALD | BN4: ALD | BO4: ALD | BP4: ALD | BQ4: ALD | BR4: ALD | BS4: ALD | BT4: ALD | BU4: ALD | BV4: ALD | BW4: ALD | BX4: ALD | BY4: ALD | BZ4: ALD | CA4: ALD | CB4: ALD | CC4: ALD | CD4: ALD | CE4: ALD | CF4: ALD | CG4: ALD | CH4: ALD | CI4: ALD | CJ4: ALD | CK4: ALD | CL4: ALD | CM4: -99 | CN4: -99 | CO4: Europe | CP4: Europe | CQ4: Northern Europe | CR4: Europe & Central Asia | CS4: 5 | CT4: 13 | CU4: 5 | CV4: 5 | CW4: -99 | CX4: 0 | CY4: 5 | CZ4: 10 | DA4: 19.869671 | DB4: 60.156467 | DC4: 1159320621 | DD4: Q5689 | DE4: Ø¬Ø²Ø± Ø£ÙˆÙ„Ø§Ù†Ø¯ | DF4: à¦…à¦²à¦¾à¦¨à§à¦¦ à¦¦à§à¦¬à§€à¦ªà¦ªà§à¦žà§à¦œ | DG4: Ã…land | DH4: Ã…land | DI4: Ã…land | DJ4: Ø¬Ø²Ø§ÛŒØ± Ø§Ù„Ù†Ø¯ | DK4: Ã…land | DL4: ÎÎ»Î±Î½Ï„ | DM4: ××•×œ× ×“ | DN4: à¤‘à¤²à¥ˆà¤£à¥à¤¡ à¤¦à¥à¤µà¥€à¤ªà¤¸à¤®à¥‚à¤¹ | DO4: Ã…land | DP4: Ã…land | DQ4: Isole Ã…land | DR4: ã‚ªãƒ¼ãƒ©ãƒ³ãƒ‰è«¸å³¶ | DS4: ì˜¬ëž€ë“œ ì œë„ | DT4: Ã…land | DU4: Wyspy Alandzkie | DV4: Ã…land | DW4: ÐÐ»Ð°Ð½Ð´ÑÐºÐ¸Ðµ Ð¾ÑÑ‚Ñ€Ð¾Ð²Ð° | DX4: Ã…land | DY4: Ã…land | DZ4: ÐÐ»Ð°Ð½Ð´ÑÑŒÐºÑ– Ð¾ÑÑ‚Ñ€Ð¾Ð²Ð¸ | EA4: Ø¬Ø²Ø§Ø¦Ø± Ø§ÛŒÙ„Ø§Ù†Úˆ | EB4: Ã…land | EC4: å¥¥å…° | ED4: å¥§è˜­ | EE4: Admin-0 dependency | EG4: Admin-0 dependency | EJ4: Unrecognized | EL4: Unrecognized
A5: Albania | B5: Admin-0 country | C5: 0 | D5: 6 | E5: Albania | F5: ALB | G5: 0 | H5: 2 | I5: Sovereign country | J5: 1 | K5: Albania | L5: ALB | M5: 0 | N5: Albania | O5: ALB | P5: 0 | Q5: Albania | R5: ALB | S5: 0 | T5: Albania | U5: ALB | V5: Albania | X5: Alb. | Y5: AL | Z5: Republic of Albania | AB5: Albania | AE5: Albania | AG5: 1 | AH5: 4 | AI5: 1 | AJ5: 6 | AK5: 2854191 | AL5: 12 | AM5: 2019 | AN5: 15279 | AO5: 2019 | AP5: 6. Developing region | AQ5: 4. Lower middle income | AR5: AL | AS5: AL | AT5: AL | AU5: ALB | AV5: ALB | AW5: 8 | AX5: 8 | AY5: 8 | AZ5: AL | BA5: ALB | BB5: 23424742 | BC5: 23424742 | BD5: Exact WOE match as country | BE5: ALB | BG5: ALB | BH5: ALB | BI5: ALB | BJ5: ALB | BK5: ALB | BL5: ALB | BM5: ALB | BN5: ALB | BO5: ALB | BP5: ALB | BQ5: ALB | BR5: ALB | BS5: ALB | BT5: ALB | BU5: ALB | BV5: ALB | BW5: ALB | BX5: ALB | BY5: ALB | BZ5: ALB | CA5: ALB | CB5: ALB | CC5: ALB | CD5: ALB | CE5: ALB | CF5: ALB | CG5: ALB | CH5: ALB | CI5: ALB | CJ5: ALB | CK5: ALB | CL5: ALB | CM5: -99 | CN5: -99 | CO5: Europe | CP5: Europe | CQ5: Southern Europe | CR5: Europe & Central Asia | CS5: 7 | CT5: 7 | CU5: 4 | CV5: -99 | CW5: 1 | CX5: 0 | CY5: 5 | CZ5: 10 | DA5: 20.11384 | DB5: 40.654855 | DC5: 1159320325 | DD5: Q222 | DE5: Ø£Ù„Ø¨Ø§Ù†ÙŠØ§ | DF5: à¦†à¦²à¦¬à§‡à¦¨à¦¿à¦¯à¦¼à¦¾ | DG5: Albanien | DH5: Albania | DI5: Albania | DJ5: Ø¢Ù„Ø¨Ø§Ù†ÛŒ | DK5: Albanie | DL5: Î‘Î»Î²Î±Î½Î¯Î± | DM5: ××œ×‘× ×™×” | DN5: à¤…à¤²à¥à¤¬à¤¾à¤¨à¤¿à¤¯à¤¾ | DO5: AlbÃ¡nia | DP5: Albania | DQ5: Albania | DR5: ã‚¢ãƒ«ãƒãƒ‹ã‚¢ | DS5: ì•Œë°”ë‹ˆì•„ | DT5: AlbaniÃ« | DU5: Albania | DV5: AlbÃ¢nia | DW5: ÐÐ»Ð±Ð°Ð½Ð¸Ñ | DX5: Albanien | DY5: Arnavutluk | DZ5: ÐÐ»Ð±Ð°Ð½Ñ–Ñ | EA5: Ø§Ù„Ø¨Ø§Ù†ÛŒØ§ | EB5: Albania | EC5: é˜¿å°”å·´å°¼äºš | ED5: é˜¿çˆ¾å·´å°¼äºž | EE5: Admin-0 country | EG5: Admin-0 country
A6: Algeria | B6: Admin-0 country | C6: 0 | D6: 3 | E6: Algeria | F6: DZA | G6: 0 | H6: 2 | I6: Sovereign country | J6: 1 | K6: Algeria | L6: DZA | M6: 0 | N6: Algeria | O6: DZA | P6: 0 | Q6: Algeria | R6: DZA | S6: 0 | T6: Algeria | U6: DZA | V6: Algeria | X6: Alg. | Y6: DZ | Z6: People's Democratic Republic of Algeria | AB6: Algeria | AE6: Algeria | AG6: 5 | AH6: 1 | AI6: 6 | AJ6: 3 | AK6: 43053054 | AL6: 15 | AM6: 2019 | AN6: 171091 | AO6: 2019 | AP6: 6. Developing region | AQ6: 3. Upper middle income | AR6: AG | AS6: DZ | AT6: DZ | AU6: DZA | AV6: DZA | AW6: 12 | AX6: 12 | AY6: 12 | AZ6: DZ | BA6: DZA | BB6: 23424740 | BC6: 23424740 | BD6: Exact WOE match as country | BE6: DZA | BG6: DZA | BH6: DZA | BI6: DZA | BJ6: DZA | BK6: DZA | BL6: DZA | BM6: DZA | BN6: DZA | BO6: DZA | BP6: DZA | BQ6: DZA | BR6: DZA | BS6: DZA | BT6: DZA | BU6: DZA | BV6: DZA | BW6: DZA | BX6: DZA | BY6: DZA | BZ6: DZA | CA6: DZA | CB6: DZA | CC6: DZA | CD6: DZA | CE6: DZA | CF6: DZA | CG6: DZA | CH6: DZA | CI6: DZA | CJ6: DZA | CK6: DZA | CL6: DZA | CM6: -99 | CN6: -99 | CO6: Africa | CP6: Africa | CQ6: Northern Africa | CR6: Middle East & North Africa | CS6: 7 | CT6: 7 | CU6: 4 | CV6: -99 | CW6: 1 | CX6: 0 | CY6: 2.5 | CZ6: 7 | DA6: 2.808241 | DB6: 27.397406 | DC6: 1159320565 | DD6: Q262 | DE6: Ø§Ù„Ø¬Ø²Ø§Ø¦Ø± | DF6: à¦†à¦²à¦œà§‡à¦°à¦¿à¦¯à¦¼à¦¾ | DG6: Algerien | DH6: Algeria | DI6: Argelia | DJ6: Ø§Ù„Ø¬Ø²Ø§ÛŒØ± | DK6: AlgÃ©rie | DL6: Î‘Î»Î³ÎµÏÎ¯Î± | DM6: ××œ×’'×™×¨×™×” | DN6: à¤…à¤²à¥à¤œà¥€à¤°à¤¿à¤¯à¤¾ | DO6: AlgÃ©ria | DP6: Aljazair | DQ6: Algeria | DR6: ã‚¢ãƒ«ã‚¸ã‚§ãƒªã‚¢ | DS6: ì•Œì œë¦¬ | DT6: Algerije | DU6: Algieria | DV6: ArgÃ©lia | DW6: ÐÐ»Ð¶Ð¸Ñ€ | DX6: Algeriet | DY6: Cezayir | DZ6: ÐÐ»Ð¶Ð¸Ñ€ | EA6: Ø§Ù„Ø¬Ø²Ø§Ø¦Ø± | EB6: AlgÃ©rie | EC6: é˜¿å°”åŠåˆ©äºš | ED6: é˜¿çˆ¾åŠåˆ©äºž | EE6: Admin-0 country | EG6: Admin-0 country
A7: American Samoa | B7: Admin-0 country | C7: 5 | D7: 4 | E7: United States of America | F7: US1 | G7: 1 | H7: 2 | I7: Dependency | J7: 1 | K7: American Samoa | L7: ASM | M7: 0 | N7: American Samoa | O7: ASM | P7: 0 | Q7: American Samoa | R7: ASM | S7: 0 | T7: American Samoa | U7: ASM | V7: American Samoa | X7: Am. Samoa | Y7: AS | Z7: American Samoa | AB7: American Samoa | AC7: U.S.A. | AE7: American Samoa | AG7: 4 | AH7: 5 | AI7: 1 | AJ7: 1 | AK7: 55312 | AL7: 8 | AM7: 2019 | AN7: 636 | AO7: 2018 | AP7: 6. Developing region | AQ7: 3. Upper middle income | AR7: AQ | AS7: AS | AT7: AS | AU7: ASM | AV7: ASM | AW7: 16 | AX7: 16 | AY7: 16 | AZ7: AS | BA7: ASM | BB7: 23424746 | BC7: 23424746 | BD7: Exact WOE match as country | BE7: ASM | BG7: ASM | BH7: ASM | BI7: ASM | BJ7: ASM | BK7: ASM | BL7: ASM | BM7: ASM | BN7: ASM | BO7: ASM | BP7: ASM | BQ7: ASM | BR7: ASM | BS7: ASM | BT7: ASM | BU7: ASM | BV7: ASM | BW7: ASM | BX7: ASM | BY7: ASM | BZ7: ASM | CA7: ASM | CB7: ASM | CC7: ASM | CD7: ASM | CE7: ASM | CF7: ASM | CG7: ASM | CH7: ASM | CI7: ASM | CJ7: ASM | CK7: ASM | CL7: ASM | CM7: -99 | CN7: -99 | CO7: Oceania | CP7: Oceania | CQ7: Polynesia | CR7: East Asia & Pacific | CS7: 14 | CT7: 14 | CU7: 9 | CV7: 3 | CW7: -99 | CX7: 0 | CY7: 4 | CZ7: 9 | DA7: -170.74715 | DB7: -14.32671 | DC7: 1159321357 | DD7: Q16641 | DE7: Ø³Ø§Ù…ÙˆØ§ Ø§Ù„Ø£Ù…Ø±ÙŠÙƒÙŠØ© | DF7: à¦®à¦¾à¦°à§à¦•à¦¿à¦¨ à¦¸à¦¾à¦®à§‹à¦¯à¦¼à¦¾ | DG7: Amerikanisch-Samoa | DH7: American Samoa | DI7: Samoa Estadounidense | DJ7: Ø³Ø§Ù…ÙˆØ¢ÛŒ Ø¢Ù…Ø±ÛŒÚ©Ø§ | DK7: Samoa amÃ©ricaines | DL7: Î‘Î¼ÎµÏÎ¹ÎºÎ±Î½Î¹ÎºÎ® Î£Î±Î¼ÏŒÎ± | DM7: ×¡×ž×•××” ×”××ž×¨×™×§× ×™×ª | DN7: à¤…à¤®à¥‡à¤°à¤¿à¤•à¥€ à¤¸à¤®à¥‹à¤† | DO7: Amerikai Szamoa | DP7: Samoa Amerika | DQ7: Samoa Americane | DR7: ã‚¢ãƒ¡ãƒªã‚«é ˜ã‚µãƒ¢ã‚¢ | DS7: ì•„ë©”ë¦¬ì¹¸ì‚¬ëª¨ì•„ | DT7: Amerikaans-Samoa | DU7: Samoa AmerykaÅ„skie | DV7: Samoa Americana | DW7: ÐÐ¼ÐµÑ€Ð¸ÐºÐ°Ð½ÑÐºÐ¾Ðµ Ð¡Ð°Ð¼Ð¾Ð° | DX7: Amerikanska Samoa | DY7: Amerikan SamoasÄ± | DZ7: Ð¡Ñ…Ñ–Ð´Ð½Ðµ Ð¡Ð°Ð¼Ð¾Ð° | EA7: Ø§Ù…Ø±ÛŒÚ©ÛŒ Ø³Ù…ÙˆÙˆØ§ | EB7: Samoa thuá»™c Má»¹ | EC7: ç¾Žå±žè¨æ‘©äºš | ED7: ç¾Žå±¬è–©æ‘©äºž | EE7: Admin-0 dependency | EG7: Admin-0 dependency
A8: Andorra | B8: Admin-0 country | C8: 0 | D8: 6 | E8: Andorra | F8: AND | G8: 0 | H8: 2 | I8: Sovereign country | J8: 1 | K8: Andorra | L8: AND | M8: 0 | N8: Andorra | O8: AND | P8: 0 | Q8: Andorra | R8: AND | S8: 0 | T8: Andorra | U8: AND | V8: Andorra | X8: And. | Y8: AND | Z8: Principality of Andorra | AB8: Andorra | AE8: Andorra | AG8: 1 | AH8: 4 | AI8: 1 | AJ8: 8 | AK8: 77142 | AL8: 8 | AM8: 2019 | AN8: 3154 | AO8: 2019 | AP8: 2. Developed region: nonG7 | AQ8: 2. High income: nonOECD | AR8: AN | AS8: AD | AT8: AD | AU8: AND | AV8: AND | AW8: 20 | AX8: 20 | AY8: 20 | AZ8: AD | BA8: ADO | BB8: 23424744 | BC8: 23424744 | BD8: Exact WOE match as country | BE8: AND | BG8: AND | BH8: AND | BI8: AND | BJ8: AND | BK8: AND | BL8: AND | BM8: AND | BN8: AND | BO8: AND | BP8: AND | BQ8: AND | BR8: AND | BS8: AND | BT8: AND | BU8: AND | BV8: AND | BW8: AND | BX8: AND | BY8: AND | BZ8: AND | CA8: AND | CB8: AND | CC8: AND | CD8: AND | CE8: AND | CF8: AND | CG8: AND | CH8: AND | CI8: AND | CJ8: AND | CK8: AND | CL8: AND | CM8: -99 | CN8: -99 | CO8: Europe | CP8: Europe | CQ8: Southern Europe | CR8: Europe & Central Asia | CS8: 7 | CT8: 7 | CU8: 4 | CV8: 5 | CW8: 1 | CX8: 0 | CY8: 5 | CZ8: 10 | DA8: 1.539409 | DB8: 42.547643 | DC8: 1159320327 | DD8: Q228 | DE8: Ø£Ù†Ø¯ÙˆØ±Ø§ | DF8: à¦…à§à¦¯à¦¾à¦¨à§à¦¡à§‹à¦°à¦¾ | DG8: Andorra | DH8: Andorra | DI8: Andorra | DJ8: Ø¢Ù†Ø¯ÙˆØ±Ø§ | DK8: Andorre | DL8: Î‘Î½Î´ÏŒÏÏÎ± | DM8: ×× ×“×•×¨×” | DN8: à¤…à¤£à¥à¤¡à¥‹à¤°à¤¾ | DO8: Andorra | DP8: Andorra | DQ8: Andorra | DR8: ã‚¢ãƒ³ãƒ‰ãƒ© | DS8: ì•ˆë„ë¼ | DT8: Andorra | DU8: Andora | DV8: Andorra | DW8: ÐÐ½Ð´Ð¾Ñ€Ñ€Ð° | DX8: Andorra | DY8: Andorra | DZ8: ÐÐ½Ð´Ð¾Ñ€Ñ€Ð° | EA8: Ø§Ù†ÚˆÙˆØ±Ø§ | EB8: Andorra | EC8: å®‰é“å°” | ED8: å®‰é“çˆ¾ | EE8: Admin-0 country | EG8: Admin-0 country
A9: Angola | B9: Admin-0 country | C9: 0 | D9: 3 | E9: Angola | F9: AGO | G9: 0 | H9: 2 | I9: Sovereign country | J9: 1 | K9: Angola | L9: AGO | M9: 0 | N9: Angola | O9: AGO | P9: 0 | Q9: Angola | R9: AGO | S9: 0 | T9: Angola | U9: AGO | V9: Angola | X9: Ang. | Y9: AO | Z9: People's Republic of Angola | AB9: Angola | AE9: Angola | AG9: 3 | AH9: 2 | AI9: 6 | AJ9: 1 | AK9: 31825295 | AL9: 15 | AM9: 2019 | AN9: 88815 | AO9: 2019 | AP9: 7. Least developed region | AQ9: 3. Upper middle income | AR9: AO | AS9: AO | AT9: AO | AU9: AGO | AV9: AGO | AW9: 24 | AX9: 24 | AY9: 24 | AZ9: AO | BA9: AGO | BB9: 23424745 | BC9: 23424745 | BD9: Exact WOE match as country | BE9: AGO | BG9: AGO | BH9: AGO | BI9: AGO | BJ9: AGO | BK9: AGO | BL9: AGO | BM9: AGO | BN9: AGO | BO9: AGO | BP9: AGO | BQ9: AGO | BR9: AGO | BS9: AGO | BT9: AGO | BU9: AGO | BV9: AGO | BW9: AGO | BX9: AGO | BY9: AGO | BZ9: AGO | CA9: AGO | CB9: AGO | CC9: AGO | CD9: AGO | CE9: AGO | CF9: AGO | CG9: AGO | CH9: AGO | CI9: AGO | CJ9: AGO | CK9: AGO | CL9: AGO | CM9: -99 | CN9: -99 | CO9: Africa | CP9: Africa | CQ9: Middle Africa | CR9: Sub-Saharan Africa | CS9: 6 | CT9: 6 | CU9: 4 | CV9: -99 | CW9: 1 | CX9: 0 | CY9: 3 | CZ9: 7 | DA9: 17.984249 | DB9: -12.182762 | DC9: 1159320323 | DD9: Q916 | DE9: Ø£Ù†ØºÙˆÙ„Ø§ | DF9: à¦…à§à¦¯à¦¾à¦™à§à¦—à§‹à¦²à¦¾ | DG9: Angola | DH9: Angola | DI9: Angola | DJ9: Ø¢Ù†Ú¯ÙˆÙ„Ø§ | DK9: Angola | DL9: Î‘Î½Î³ÎºÏŒÎ»Î± | DM9: ×× ×’×•×œ×” | DN9: à¤…à¤‚à¤—à¥‹à¤²à¤¾ | DO9: Angola | DP9: Angola | DQ9: Angola | DR9: ã‚¢ãƒ³ã‚´ãƒ© | DS9: ì•™ê³¨ë¼ | DT9: Angola | DU9: Angola | DV9: Angola | DW9: ÐÐ½Ð³Ð¾Ð»Ð° | DX9: Angola | DY9: Angola | DZ9: ÐÐ½Ð³Ð¾Ð»Ð° | EA9: Ø§Ù†Ú¯ÙˆÙ„Ø§ | EB9: Angola | EC9: å®‰å“¥æ‹‰ | ED9: å®‰å“¥æ‹‰ | EE9: Admin-0 country | EG9: Admin-0 country
A10: Anguilla | B10: Admin-0 country | C10: 3 | D10: 6 | E10: United Kingdom | F10: GB1 | G10: 1 | H10: 2 | I10: Dependency | J10: 1 | K10: Anguilla | L10: AIA | M10: 0 | N10: Anguilla | O10: AIA | P10: 0 | Q10: Anguilla | R10: AIA | S10: 0 | T10: Anguilla | U10: AIA | V10: Anguilla | X10: Ang. | Y10: AI | AB10: Anguilla | AC10: U.K. | AE10: Anguilla | AG10: 6 | AH10: 6 | AI10: 6 | AJ10: 3 | AK10: 14731 | AL10: 6 | AM10: 2018 | AN10: 175 | AO10: 2009 | AP10: 6. Developing region | AQ10: 3. Upper middle income | AR10: AV | AS10: AI | AT10: AI | AU10: AIA | AV10: AIA | AW10: 660 | AX10: 660 | AY10: 660 | AZ10: -99 | BA10: -99 | BB10: 23424751 | BC10: 23424751 | BD10: Exact WOE match as country | BE10: AIA | BG10: AIA | BH10: AIA | BI10: AIA | BJ10: AIA | BK10: AIA | BL10: AIA | BM10: AIA | BN10: AIA | BO10: AIA | BP10: AIA | BQ10: AIA | BR10: AIA | BS10: AIA | BT10: AIA | BU10: AIA | BV10: AIA | BW10: AIA | BX10: AIA | BY10: AIA | BZ10: AIA | CA10: AIA | CB10: AIA | CC10: AIA | CD10: AIA | CE10: AIA | CF10: AIA | CG10: AIA | CH10: AIA | CI10: AIA | CJ10: AIA | CK10: AIA | CL10: AIA | CM10: -99 | CN10: -99 | CO10: North America | CP10: Americas | CQ10: Caribbean | CR10: Latin America & Caribbean | CS10: 8 | CT10: 8 | CU10: 4 | CV10: -99 | CW10: -99 | CX10: 0 | CY10: 5 | CZ10: 10 | DA10: -63.026361 | DB10: 18.242979 | DC10: 1159320703 | DD10: Q25228 | DE10: Ø£Ù†ØºÙˆÙŠÙ„Ø§ | DF10: à¦à§à¦¯à¦¾à¦™à§à¦—à§à¦‡à¦²à¦¾ | DG10: Anguilla | DH10: Anguilla | DI10: Anguila | DJ10: Ø¢Ù†Ú¯ÙˆÛŒÙ„Ø§ | DK10: Anguilla | DL10: Î‘Î½Î³ÎºÎ¿Ï…Î¯Î»Î± | DM10: ×× ×’×•×•×™×œ×” | DN10: à¤…à¤‚à¤—à¥à¤‡à¤²à¤¾ | DO10: Anguilla | DP10: Anguilla | DQ10: Anguilla | DR10: ã‚¢ãƒ³ã‚®ãƒ© | DS10: ì•µê·ˆë¼ | DT10: Anguilla | DU10: Anguilla | DV10: Anguilla | DW10: ÐÐ½Ð³Ð¸Ð»ÑŒÑ | DX10: Anguilla | DY10: Anguilla | DZ10: ÐÐ½Ð³Ñ–Ð»ÑŒÑ | EA10: Ø§ÛŒÙ†Ú¯ÙˆÛŒÙ„Ø§ | EB10: Anguilla | EC10: å®‰åœ­æ‹‰ | ED10: å®‰å‰æ‹‰ | EE10: Admin-0 dependency | EG10: Admin-0 dependency
A11: Antarctica | B11: Admin-0 country | C11: 0 | D11: 4 | E11: Antarctica | F11: ATA | G11: 0 | H11: 2 | I11: Indeterminate | J11: 1 | K11: Antarctica | L11: ATA | M11: 0 | N11: Antarctica | O11: ATA | P11: 0 | Q11: Antarctica | R11: ATA | S11: 0 | T11: Antarctica | U11: ATA | V11: Antarctica | X11: Ant. | Y11: AQ | AC11: By treaty | AD11: Multiple claims held in abeyance by treaty | AE11: Antarctica | AG11: 4 | AH11: 5 | AI11: 1 | AJ11: -99 | AK11: 4490 | AL11: 4 | AM11: 2019 | AN11: 898 | AO11: 2013 | AP11: 6. Developing region | AQ11: 2. High income: nonOECD | AR11: AY | AS11: AQ | AT11: AQ | AU11: ATA | AV11: ATA | AW11: 10 | AX11: 10 | AY11: 10 | AZ11: -99 | BA11: -99 | BB11: 28289409 | BC11: 28289409 | BD11: Exact WOE match as country | BE11: ATA | BG11: ATA | BH11: ATA | BI11: ATA | BJ11: ATA | BK11: ATA | BL11: ATA | BM11: ATA | BN11: ATA | BO11: ATA | BP11: ATA | BQ11: ATA | BR11: ATA | BS11: ATA | BT11: ATA | BU11: ATA | BV11: ATA | BW11: ATA | BX11: ATA | BY11: ATA | BZ11: ATA | CA11: ATA | CB11: ATA | CC11: ATA | CD11: ATA | CE11: ATA | CF11: ATA | CG11: ATA | CH11: ATA | CI11: ATA | CJ11: ATA | CK11: ATA | CL11: ATA | CM11: -99 | CN11: -99 | CO11: Antarctica | CP11: Antarctica | CQ11: Antarctica | CR11: Antarctica | CS11: 10 | CT11: 10 | CU11: 4 | CV11: -99 | CW11: 1 | CX11: 0 | CY11: 4 | CZ11: 9 | DA11: 35.885455 | DB11: -79.843222 | DC11: 1159320335 | DD11: Q51 | DE11: Ø§Ù„Ù‚Ø§Ø±Ø© Ø§Ù„Ù‚Ø·Ø¨ÙŠØ© Ø§Ù„Ø¬Ù†ÙˆØ¨ÙŠØ© | DF11: à¦…à§à¦¯à¦¾à¦¨à§à¦Ÿà¦¾à¦°à§à¦•à¦Ÿà¦¿à¦•à¦¾ | DG11: Antarktika | DH11: Antarctica | DI11: AntÃ¡rtida | DJ11: Ø¬Ù†ÙˆØ¨Ú¯Ø§Ù† | DK11: Antarctique | DL11: Î‘Î½Ï„Î±ÏÎºÏ„Î¹ÎºÎ® | DM11: ×× ×˜××¨×§×˜×™×§×” | DN11: à¤…à¤‚à¤Ÿà¤¾à¤°à¥à¤•à¤Ÿà¤¿à¤•à¤¾ | DO11: Antarktika | DP11: Antartika | DQ11: Antartide | DR11: å—æ¥µå¤§é™¸ | DS11: ë‚¨ê·¹ | DT11: Antarctica | DU11: Antarktyda | DV11: AntÃ¡rtida | DW11: ÐÐ½Ñ‚Ð°Ñ€ÐºÑ‚Ð¸Ð´Ð° | DX11: Antarktis | DY11: Antarktika | DZ11: ÐÐ½Ñ‚Ð°Ñ€ÐºÑ‚Ð¸Ð´Ð° | EA11: Ø§Ù†Ù¹Ø§Ø±Ú©Ù¹Ú©Ø§ | EB11: ChÃ¢u Nam Cá»±c | EC11: å—æžæ´² | ED11: å—æ¥µæ´² | EE11: Admin-0 dependency | EG11: Admin-0 dependency
A12: Antigua and Barbuda | B12: Admin-0 country | C12: 3 | D12: 6 | E12: Antigua and Barbuda | F12: ATG | G12: 0 | H12: 2 | I12: Sovereign country | J12: 1 | K12: Antigua and Barbuda | L12: ATG | M12: 0 | N12: Antigua and Barbuda | O12: ATG | P12: 0 | Q12: Antigua and Barbuda | R12: ATG | S12: 0 | T12: Antigua and Barbuda | U12: ATG | V12: Antigua and Barb. | X12: Ant.B. | Y12: AG | Z12: Antigua and Barbuda | AB12: Antigua and Barbuda | AE12: Antigua and Barbuda | AG12: 2 | AH12: 2 | AI12: 5 | AJ12: 5 | AK12: 97118 | AL12: 8 | AM12: 2019 | AN12: 1661 | AO12: 2019 | AP12: 6. Developing region | AQ12: 3. Upper middle income | AR12: AC | AS12: AG | AT12: AG | AU12: ATG | AV12: ATG | AW12: 28 | AX12: 28 | AY12: 28 | AZ12: AG | BA12: ATG | BB12: 23424737 | BC12: 23424737 | BD12: Exact WOE match as country | BE12: ATG | BG12: ATG | BH12: ATG | BI12: ATG | BJ12: ATG | BK12: ATG | BL12: ATG | BM12: ATG | BN12: ATG | BO12: ATG | BP12: ATG | BQ12: ATG | BR12: ATG | BS12: ATG | BT12: ATG | BU12: ATG | BV12: ATG | BW12: ATG | BX12: ATG | BY12: ATG | BZ12: ATG | CA12: ATG | CB12: ATG | CC12: ATG | CD12: ATG | CE12: ATG | CF12: ATG | CG12: ATG | CH12: ATG | CI12: ATG | CJ12: ATG | CK12: ATG | CL12: ATG | CM12: -99 | CN12: -99 | CO12: North America | CP12: Americas | CQ12: Caribbean | CR12: Latin America & Caribbean | CS12: 17 | CT12: 19 | CU12: 6 | CV12: 4 | CW12: 1 | CX12: 0 | CY12: 5 | CZ12: 9.5 | DA12: -61.790612 | DB12: 17.352249 | DC12: 1159320345 | DD12: Q781 | DE12: Ø£Ù†ØªÙŠØºÙˆØ§ ÙˆØ¨Ø§Ø±Ø¨ÙˆØ¯Ø§ | DF12: à¦…à§à¦¯à¦¾à¦¨à§à¦Ÿà¦¿à¦—à§à¦¯à¦¼à¦¾ à¦“ à¦¬à¦¾à¦°à§à¦¬à§à¦¡à¦¾ | DG12: Antigua und Barbuda | DH12: Antigua and Barbuda | DI12: Antigua y Barbuda | DJ12: Ø¢Ù†ØªÛŒÚ¯ÙˆØ§ Ùˆ Ø¨Ø§Ø±Ø¨ÙˆØ¯Ø§ | DK12: Antigua-et-Barbuda | DL12: Î‘Î½Ï„Î¯Î³ÎºÎ¿Ï…Î± ÎºÎ±Î¹ ÎœÏ€Î±ÏÎ¼Ï€Î¿ÏÎ½Ï„Î± | DM12: ×× ×˜×™×’×•××” ×•×‘×¨×‘×•×“×” | DN12: à¤…à¤£à¥à¤Ÿà¥€à¤—à¥à¤† à¤”à¤° à¤¬à¤¾à¤°à¤¬à¥‚à¤¡à¤¾ | DO12: Antigua Ã©s Barbuda | DP12: Antigua dan Barbuda | DQ12: Antigua e Barbuda | DR12: ã‚¢ãƒ³ãƒ†ã‚£ã‚°ã‚¢ãƒ»ãƒãƒ¼ãƒ–ãƒ¼ãƒ€ | DS12: ì•¤í‹°ê°€ ë°”ë¶€ë‹¤ | DT12: Antigua en Barbuda | DU12: Antigua i Barbuda | DV12: AntÃ­gua e Barbuda | DW12: ÐÐ½Ñ‚Ð¸Ð³ÑƒÐ° Ð¸ Ð‘Ð°Ñ€Ð±ÑƒÐ´Ð° | DX12: Antigua och Barbuda | DY12: Antigua ve Barbuda | DZ12: ÐÐ½Ñ‚Ð¸Ð³ÑƒÐ° Ñ– Ð‘Ð°Ñ€Ð±ÑƒÐ´Ð° | EA12: Ø§ÛŒÙ†Ù¹ÛŒÚ¯ÙˆØ§ Ùˆ Ø¨Ø§Ø±Ø¨ÙˆÚˆØ§ | EB12: Antigua vÃ Barbuda | EC12: å®‰æç“œå’Œå·´å¸ƒè¾¾ | ED12: å®‰åœ°å¡åŠå·´å¸ƒé” | EE12: Admin-0 country | EG12: Admin-0 country
A13: Argentina | B13: Admin-0 country | C13: 0 | D13: 2 | E13: Argentina | F13: ARG | G13: 0 | H13: 2 | I13: Sovereign country | J13: 1 | K13: Argentina | L13: ARG | M13: 0 | N13: Argentina | O13: ARG | P13: 0 | Q13: Argentina | R13: ARG | S13: 0 | T13: Argentina | U13: ARG | V13: Argentina | X13: Arg. | Y13: AR | Z13: Argentine Republic | AB13: Argentina | AE13: Argentina | AG13: 3 | AH13: 1 | AI13: 3 | AJ13: 13 | AK13: 44938712 | AL13: 15 | AM13: 2019 | AN13: 445445 | AO13: 2019 | AP13: 5. Emerging region: G20 | AQ13: 3. Upper middle income | AR13: AR | AS13: AR | AT13: AR | AU13: ARG | AV13: ARG | AW13: 32 | AX13: 32 | AY13: 32 | AZ13: AR | BA13: ARG | BB13: 23424747 | BC13: 23424747 | BD13: Exact WOE match as country | BE13: ARG | BG13: ARG | BH13: ARG | BI13: ARG | BJ13: ARG | BK13: ARG | BL13: ARG | BM13: ARG | BN13: ARG | BO13: ARG | BP13: ARG | BQ13: ARG | BR13: ARG | BS13: ARG | BT13: ARG | BU13: ARG | BV13: ARG | BW13: ARG | BX13: ARG | BY13: ARG | BZ13: ARG | CA13: ARG | CB13: ARG | CC13: ARG | CD13: ARG | CE13: ARG | CF13: ARG | CG13: ARG | CH13: ARG | CI13: ARG | CJ13: ARG | CK13: ARG | CL13: ARG | CM13: -99 | CN13: -99 | CO13: South America | CP13: Americas | CQ13: South America | CR13: Latin America & Caribbean | CS13: 9 | CT13: 9 | CU13: 4 | CV13: -99 | CW13: 1 | CX13: 0 | CY13: 2 | CZ13: 7 | DA13: -64.173331 | DB13: -33.501159 | DC13: 1159320331 | DD13: Q414 | DE13: Ø§Ù„Ø£Ø±Ø¬Ù†ØªÙŠÙ† | DF13: à¦†à¦°à§à¦œà§‡à¦¨à§à¦Ÿà¦¿à¦¨à¦¾ | DG13: Argentinien | DH13: Argentina | DI13: Argentina | DJ13: Ø¢Ø±Ú˜Ø§Ù†ØªÛŒÙ† | DK13: Argentine | DL13: Î‘ÏÎ³ÎµÎ½Ï„Î¹Î½Î® | DM13: ××¨×’× ×˜×™× ×” | DN13: à¤…à¤°à¥à¤œà¥‡à¤£à¥à¤Ÿà¥€à¤¨à¤¾ | DO13: ArgentÃ­na | DP13: Argentina | DQ13: Argentina | DR13: ã‚¢ãƒ«ã‚¼ãƒ³ãƒãƒ³ | DS13: ì•„ë¥´í—¨í‹°ë‚˜ | DT13: ArgentiniÃ« | DU13: Argentyna | DV13: Argentina | DW13: ÐÑ€Ð³ÐµÐ½Ñ‚Ð¸Ð½Ð° | DX13: Argentina | DY13: Arjantin | DZ13: ÐÑ€Ð³ÐµÐ½Ñ‚Ð¸Ð½Ð° | EA13: Ø§Ø±Ø¬Ù†Ù¹Ø§Ø¦Ù† | EB13: Argentina | EC13: é˜¿æ ¹å»· | ED13: é˜¿æ ¹å»· | EE13: Admin-0 country | EG13: Admin-0 country
A14: Armenia | B14: Admin-0 country | C14: 0 | D14: 6 | E14: Armenia | F14: ARM | G14: 0 | H14: 2 | I14: Sovereign country | J14: 1 | K14: Armenia | L14: ARM | M14: 0 | N14: Armenia | O14: ARM | P14: 0 | Q14: Armenia | R14: ARM | S14: 0 | T14: Armenia | U14: ARM | V14: Armenia | X14: Arm. | Y14: ARM | Z14: Republic of Armenia | AB14: Armenia | AE14: Armenia | AG14: 3 | AH14: 1 | AI14: 2 | AJ14: 10 | AK14: 2957731 | AL14: 12 | AM14: 2019 | AN14: 13672 | AO14: 2019 | AP14: 6. Developing region | AQ14: 4. Lower middle income | AR14: AM | AS14: AM | AT14: AM | AU14: ARM | AV14: ARM | AW14: 51 | AX14: 51 | AY14: 51 | AZ14: AM | BA14: ARM | BB14: 23424743 | BC14: 23424743 | BD14: Exact WOE match as country | BE14: ARM | BG14: ARM | BH14: ARM | BI14: ARM | BJ14: ARM | BK14: ARM | BL14: ARM | BM14: ARM | BN14: ARM | BO14: ARM | BP14: ARM | BQ14: ARM | BR14: ARM | BS14: ARM | BT14: ARM | BU14: ARM | BV14: ARM | BW14: ARM | BX14: ARM | BY14: ARM | BZ14: ARM | CA14: ARM | CB14: ARM | CC14: ARM | CD14: ARM | CE14: ARM | CF14: ARM | CG14: ARM | CH14: ARM | CI14: ARM | CJ14: ARM | CK14: ARM | CL14: ARM | CM14: -99 | CN14: -99 | CO14: Asia | CP14: Asia | CQ14: Western Asia | CR14: Europe & Central Asia | CS14: 7 | CT14: 7 | CU14: 4 | CV14: -99 | CW14: 1 | CX14: 0 | CY14: 5 | CZ14: 10 | DA14: 44.800564 | DB14: 40.459077 | DC14: 1159320333 | DD14: Q399 | DE14: Ø£Ø±Ù…ÙŠÙ†ÙŠØ§ | DF14: à¦†à¦°à§à¦®à§‡à¦¨à¦¿à¦¯à¦¼à¦¾ | DG14: Armenien | DH14: Armenia | DI14: Armenia | DJ14: Ø§Ø±Ù…Ù†Ø³ØªØ§Ù† | DK14: ArmÃ©nie | DL14: Î‘ÏÎ¼ÎµÎ½Î¯Î± | DM14: ××¨×ž× ×™×” | DN14: à¤†à¤°à¥à¤®à¥€à¤¨à¤¿à¤¯à¤¾ | DO14: Ã–rmÃ©nyorszÃ¡g | DP14: Armenia | DQ14: Armenia | DR14: ã‚¢ãƒ«ãƒ¡ãƒ‹ã‚¢ | DS14: ì•„ë¥´ë©”ë‹ˆì•„ | DT14: ArmeniÃ« | DU14: Armenia | DV14: ArmÃ©nia | DW14: ÐÑ€Ð¼ÐµÐ½Ð¸Ñ | DX14: Armenien | DY14: Ermenistan | DZ14: Ð’Ñ–Ñ€Ð¼ÐµÐ½Ñ–Ñ | EA14: Ø¢Ø±Ù…ÛŒÙ†ÛŒØ§ | EB14: Armenia | EC14: äºšç¾Žå°¼äºš | ED14: äºžç¾Žå°¼äºž | EE14: Admin-0 country | EG14: Admin-0 country
